<?xml version="1.0" ?>
<!-- =================================================================================== -->
<!-- |    This document was autogenerated by xacro from jelly.urdf.xacro               | -->
<!-- |    EDITING THIS FILE BY HAND IS NOT RECOMMENDED                                 | -->
<!-- =================================================================================== -->
<robot name="blue_description" xmlns:xacro="http://ros.org/wiki/xacro">
  <!-- <xacro:arg name="is_gazebo" default="false" /> -->
  <!-- <xacro:property name="is_gazebo" value="$(arg is_gazebo)" /> -->
  <link name="base_link">
    <inertial>
      <origin rpy="0 0 0" xyz="1.3878E-16 7.5298E-19 -0.00024739"/>
      <mass value="1.4036"/>
      <inertia ixx="0.010824" ixy="-3.2526E-18" ixz="8.8557E-19" iyy="0.019805" iyz="9.2004E-19" izz="0.025106"/>
    </inertial>
    <visual>
      <origin rpy="0 0 0" xyz="0 0 0"/>
      <geometry>
        <mesh filename="package://jelly_descriptions/meshes/base_link.STL"/>
      </geometry>
      <material name="">
        <color rgba="0.29804 0.29765 0.29941 1"/>
      </material>
    </visual>
    <collision>
      <origin rpy="0 0 0" xyz="0 0 0"/>
      <geometry>
        <mesh filename="package://jelly_descriptions/meshes/base_link.STL"/>
      </geometry>
    </collision>
  </link>
  <link name="FR_hip_link">
    <inertial>
      <origin rpy="0 0 0" xyz="-0.050171 -0.014879 2.5931E-05"/>
      <mass value="0.39719"/>
      <inertia ixx="0.0004047" ixy="0.00028697" ixz="2.6664E-07" iyy="0.00044289" iyz="-3.1906E-07" izz="0.00079608"/>
    </inertial>
    <visual>
      <origin rpy="0 0 0" xyz="0 0 0"/>
      <geometry>
        <mesh filename="package://jelly_descriptions/meshes/hip_link.STL"/>
      </geometry>
      <material name="">
        <color rgba="0.89804 0.91765 0.92941 1"/>
      </material>
    </visual>
    <collision>
      <origin rpy="0 0 0" xyz="0 0 0"/>
      <geometry>
        <mesh filename="package://jelly_descriptions/meshes/hip_link.STL"/>
      </geometry>
    </collision>
  </link>
  <joint name="FR_hip_joint" type="continuous">
    <origin rpy="0 0 0" xyz="0.28135 -0.11 0"/>
    <parent link="base_link"/>
    <child link="FR_hip_link"/>
    <axis xyz="1 0 0"/>
  </joint>
  <link name="FR_upper_leg_link">
    <inertial>
      <origin rpy="0 0 0" xyz="0.0002142 -0.021966 -0.12486"/>
      <mass value="0.6645"/>
      <inertia ixx="0.0067989" ixy="2.0009E-06" ixz="6.14E-07" iyy="0.0067314" iyz="1.4199E-06" izz="0.00018916"/>
    </inertial>
    <visual>
      <origin rpy="0 0 0" xyz="0 0 0"/>
      <geometry>
        <mesh filename="package://jelly_descriptions/meshes/upper_leg_link.STL"/>
      </geometry>
      <material name="">
        <color rgba="0.19804 0.11765 0.12941 1"/>
      </material>
    </visual>
    <collision>
      <origin rpy="0 0 0" xyz="0 0 0"/>
      <geometry>
        <mesh filename="package://jelly_descriptions/meshes/upper_leg_link.STL"/>
      </geometry>
    </collision>
  </link>
  <joint name="FR_upper_leg_joint" type="continuous">
    <origin rpy="0 0 0" xyz="0 -0.046 0"/>
    <parent link="FR_hip_link"/>
    <child link="FR_upper_leg_link"/>
    <axis xyz="0 1 0"/>
  </joint>
  <link name="FR_lower_leg_link">
    <inertial>
      <origin rpy="0 0 0" xyz="-1.4945E-06 -0.011905 -0.12333"/>
      <mass value="0.17273"/>
      <inertia ixx="0.0018547" ixy="-6.8019E-09" ixz="3.1812E-08" iyy="0.0017651" iyz="0.00025365" izz="8.9626E-05"/>
    </inertial>
    <visual>
      <origin rpy="0 0 0" xyz="0 0 0"/>
      <geometry>
        <mesh filename="package://jelly_descriptions/meshes/lower_leg_link.STL"/>
      </geometry>
      <material name="">
        <color rgba="0.89804 0.91765 0.92941 1"/>
      </material>
    </visual>
    <collision>
      <origin rpy="0 0 0" xyz="0 0 0"/>
      <geometry>
        <mesh filename="package://jelly_descriptions/meshes/lower_leg_link.STL"/>
      </geometry>
    </collision>
  </link>
  <joint name="FR_lower_leg_joint" type="continuous">
    <origin rpy="0 0 0" xyz="0 0 -0.25"/>
    <parent link="FR_upper_leg_link"/>
    <child link="FR_lower_leg_link"/>
    <axis xyz="0 1 0"/>
  </joint>
  <link name="FR_foot_link"/>
  <joint name="FR_foot_joint" type="fixed">
    <origin rpy="0 0 0" xyz="0 0 -0.25116"/>
    <parent link="FR_lower_leg_link"/>
    <child link="FR_foot_link"/>
    <axis xyz="0 0 0"/>
  </joint>
  <link name="FL_hip_link">
    <inertial>
      <origin rpy="3.1415926535 0 0" xyz="-0.050171 -0.014879 2.5931E-05"/>
      <mass value="0.39719"/>
      <inertia ixx="0.0004047" ixy="0.00028697" ixz="2.6664E-07" iyy="0.00044289" iyz="-3.1906E-07" izz="0.00079608"/>
    </inertial>
    <visual>
      <origin rpy="3.1415926535 0 0" xyz="0 0 0"/>
      <geometry>
        <mesh filename="package://jelly_descriptions/meshes/hip_link.STL"/>
      </geometry>
      <material name="">
        <color rgba="0.89804 0.91765 0.92941 1"/>
      </material>
    </visual>
    <collision>
      <origin rpy="0 0 0" xyz="3.1415926535 0 0"/>
      <geometry>
        <mesh filename="package://jelly_descriptions/meshes/hip_link.STL"/>
      </geometry>
    </collision>
  </link>
  <joint name="FL_hip_joint" type="continuous">
    <origin rpy="0 0 0" xyz="0.28135 0.11 0"/>
    <parent link="base_link"/>
    <child link="FL_hip_link"/>
    <axis xyz="1 0 0"/>
  </joint>
  <link name="FL_upper_leg_link">
    <inertial>
      <origin rpy="0 0 3.1415926535" xyz="0.0002142 -0.021966 -0.12486"/>
      <mass value="0.6645"/>
      <inertia ixx="0.0067989" ixy="2.0009E-06" ixz="6.14E-07" iyy="0.0067314" iyz="1.4199E-06" izz="0.00018916"/>
    </inertial>
    <visual>
      <origin rpy="0 0 3.1415926535" xyz="0 0 0"/>
      <geometry>
        <mesh filename="package://jelly_descriptions/meshes/upper_leg_link.STL"/>
      </geometry>
      <material name="">
        <color rgba="0.19804 0.11765 0.12941 1"/>
      </material>
    </visual>
    <collision>
      <origin rpy="0 0 3.1415926535" xyz="0 0 0"/>
      <geometry>
        <mesh filename="package://jelly_descriptions/meshes/upper_leg_link.STL"/>
      </geometry>
    </collision>
  </link>
  <joint name="FL_upper_leg_joint" type="continuous">
    <origin rpy="0 0 0" xyz="0 0.046 0"/>
    <parent link="FL_hip_link"/>
    <child link="FL_upper_leg_link"/>
    <axis xyz="0 1 0"/>
  </joint>
  <link name="FL_lower_leg_link">
    <inertial>
      <origin rpy="0 0 3.1415926535" xyz="-1.4945E-06 -0.011905 -0.12333"/>
      <mass value="0.17273"/>
      <inertia ixx="0.0018547" ixy="-6.8019E-09" ixz="3.1812E-08" iyy="0.0017651" iyz="0.00025365" izz="8.9626E-05"/>
    </inertial>
    <visual>
      <origin rpy="0 0 3.1415926535" xyz="0 0 0"/>
      <geometry>
        <mesh filename="package://jelly_descriptions/meshes/lower_leg_link.STL"/>
      </geometry>
      <material name="">
        <color rgba="0.89804 0.91765 0.92941 1"/>
      </material>
    </visual>
    <collision>
      <origin rpy="0 0 3.1415926535" xyz="0 0 0"/>
      <geometry>
        <mesh filename="package://jelly_descriptions/meshes/lower_leg_link.STL"/>
      </geometry>
    </collision>
  </link>
  <joint name="FL_lower_leg_joint" type="continuous">
    <origin rpy="0 0 0" xyz="0 0 -0.25"/>
    <parent link="FL_upper_leg_link"/>
    <child link="FL_lower_leg_link"/>
    <axis xyz="0 1 0"/>
  </joint>
  <link name="FL_foot_link"/>
  <joint name="FL_foot_joint" type="fixed">
    <origin rpy="0 0 0" xyz="0 0 -0.25116"/>
    <parent link="FL_lower_leg_link"/>
    <child link="FL_foot_link"/>
    <axis xyz="0 0 0"/>
  </joint>
  <link name="RR_hip_link">
    <inertial>
      <origin rpy="3.1415926535 0 3.1415926535" xyz="-0.050171 -0.014879 2.5931E-05"/>
      <mass value="0.39719"/>
      <inertia ixx="0.0004047" ixy="0.00028697" ixz="2.6664E-07" iyy="0.00044289" iyz="-3.1906E-07" izz="0.00079608"/>
    </inertial>
    <visual>
      <origin rpy="3.1415926535 0 3.1415926535" xyz="0 0 0"/>
      <geometry>
        <mesh filename="package://jelly_descriptions/meshes/hip_link.STL"/>
      </geometry>
      <material name="">
        <color rgba="0.89804 0.91765 0.92941 1"/>
      </material>
    </visual>
    <collision>
      <origin rpy="0 0 0" xyz="3.1415926535 0 3.1415926535"/>
      <geometry>
        <mesh filename="package://jelly_descriptions/meshes/hip_link.STL"/>
      </geometry>
    </collision>
  </link>
  <joint name="RR_hip_joint" type="continuous">
    <origin rpy="0 0 0" xyz="-0.28135 -0.11 0"/>
    <parent link="base_link"/>
    <child link="RR_hip_link"/>
    <axis xyz="1 0 0"/>
  </joint>
  <link name="RR_upper_leg_link">
    <inertial>
      <origin rpy="0 0 0" xyz="0.0002142 -0.021966 -0.12486"/>
      <mass value="0.6645"/>
      <inertia ixx="0.0067989" ixy="2.0009E-06" ixz="6.14E-07" iyy="0.0067314" iyz="1.4199E-06" izz="0.00018916"/>
    </inertial>
    <visual>
      <origin rpy="0 0 0" xyz="0 0 0"/>
      <geometry>
        <mesh filename="package://jelly_descriptions/meshes/upper_leg_link.STL"/>
      </geometry>
      <material name="">
        <color rgba="0.19804 0.11765 0.12941 1"/>
      </material>
    </visual>
    <collision>
      <origin rpy="0 0 0" xyz="0 0 0"/>
      <geometry>
        <mesh filename="package://jelly_descriptions/meshes/upper_leg_link.STL"/>
      </geometry>
    </collision>
  </link>
  <joint name="RR_upper_leg_joint" type="continuous">
    <origin rpy="0 0 0" xyz="0 -0.046 0"/>
    <parent link="RR_hip_link"/>
    <child link="RR_upper_leg_link"/>
    <axis xyz="0 1 0"/>
  </joint>
  <link name="RR_lower_leg_link">
    <inertial>
      <origin rpy="0 0 0" xyz="-1.4945E-06 -0.011905 -0.12333"/>
      <mass value="0.17273"/>
      <inertia ixx="0.0018547" ixy="-6.8019E-09" ixz="3.1812E-08" iyy="0.0017651" iyz="0.00025365" izz="8.9626E-05"/>
    </inertial>
    <visual>
      <origin rpy="0 0 0" xyz="0 0 0"/>
      <geometry>
        <mesh filename="package://jelly_descriptions/meshes/lower_leg_link.STL"/>
      </geometry>
      <material name="">
        <color rgba="0.89804 0.91765 0.92941 1"/>
      </material>
    </visual>
    <collision>
      <origin rpy="0 0 0" xyz="0 0 0"/>
      <geometry>
        <mesh filename="package://jelly_descriptions/meshes/lower_leg_link.STL"/>
      </geometry>
    </collision>
  </link>
  <joint name="RR_lower_leg_joint" type="continuous">
    <origin rpy="0 0 0" xyz="0 0 -0.25"/>
    <parent link="RR_upper_leg_link"/>
    <child link="RR_lower_leg_link"/>
    <axis xyz="0 1 0"/>
  </joint>
  <link name="RR_foot_link"/>
  <joint name="RR_foot_joint" type="fixed">
    <origin rpy="0 0 0" xyz="0 0 -0.25116"/>
    <parent link="RR_lower_leg_link"/>
    <child link="RR_foot_link"/>
    <axis xyz="0 0 0"/>
  </joint>
  <link name="RL_hip_link">
    <inertial>
      <origin rpy="0 0 3.1415926535" xyz="-0.050171 -0.014879 2.5931E-05"/>
      <mass value="0.39719"/>
      <inertia ixx="0.0004047" ixy="0.00028697" ixz="2.6664E-07" iyy="0.00044289" iyz="-3.1906E-07" izz="0.00079608"/>
    </inertial>
    <visual>
      <origin rpy="0 0 3.1415926535" xyz="0 0 0"/>
      <geometry>
        <mesh filename="package://jelly_descriptions/meshes/hip_link.STL"/>
      </geometry>
      <material name="">
        <color rgba="0.89804 0.91765 0.92941 1"/>
      </material>
    </visual>
    <collision>
      <origin rpy="0 0 0" xyz="0 0 3.1415926535"/>
      <geometry>
        <mesh filename="package://jelly_descriptions/meshes/hip_link.STL"/>
      </geometry>
    </collision>
  </link>
  <joint name="RL_hip_joint" type="continuous">
    <origin rpy="0 0 0" xyz="-0.28135 0.11 0"/>
    <parent link="base_link"/>
    <child link="RL_hip_link"/>
    <axis xyz="1 0 0"/>
  </joint>
  <link name="RL_upper_leg_link">
    <inertial>
      <origin rpy="0 0 3.1415926535" xyz="0.0002142 -0.021966 -0.12486"/>
      <mass value="0.6645"/>
      <inertia ixx="0.0067989" ixy="2.0009E-06" ixz="6.14E-07" iyy="0.0067314" iyz="1.4199E-06" izz="0.00018916"/>
    </inertial>
    <visual>
      <origin rpy="0 0 3.1415926535" xyz="0 0 0"/>
      <geometry>
        <mesh filename="package://jelly_descriptions/meshes/upper_leg_link.STL"/>
      </geometry>
      <material name="">
        <color rgba="0.19804 0.11765 0.12941 1"/>
      </material>
    </visual>
    <collision>
      <origin rpy="0 0 3.1415926535" xyz="0 0 0"/>
      <geometry>
        <mesh filename="package://jelly_descriptions/meshes/upper_leg_link.STL"/>
      </geometry>
    </collision>
  </link>
  <joint name="RL_upper_leg_joint" type="continuous">
    <origin rpy="0 0 0" xyz="0 0.046 0"/>
    <parent link="RL_hip_link"/>
    <child link="RL_upper_leg_link"/>
    <axis xyz="0 1 0"/>
  </joint>
  <link name="RL_lower_leg_link">
    <inertial>
      <origin rpy="0 0 3.1415926535" xyz="-1.4945E-06 -0.011905 -0.12333"/>
      <mass value="0.17273"/>
      <inertia ixx="0.0018547" ixy="-6.8019E-09" ixz="3.1812E-08" iyy="0.0017651" iyz="0.00025365" izz="8.9626E-05"/>
    </inertial>
    <visual>
      <origin rpy="0 0 3.1415926535" xyz="0 0 0"/>
      <geometry>
        <mesh filename="package://jelly_descriptions/meshes/lower_leg_link.STL"/>
      </geometry>
      <material name="">
        <color rgba="0.89804 0.91765 0.92941 1"/>
      </material>
    </visual>
    <collision>
      <origin rpy="0 0 3.1415926535" xyz="0 0 0"/>
      <geometry>
        <mesh filename="package://jelly_descriptions/meshes/lower_leg_link.STL"/>
      </geometry>
    </collision>
  </link>
  <joint name="RL_lower_leg_joint" type="continuous">
    <origin rpy="0 0 0" xyz="0 0 -0.25"/>
    <parent link="RL_upper_leg_link"/>
    <child link="RL_lower_leg_link"/>
    <axis xyz="0 1 0"/>
  </joint>
  <link name="RL_foot_link"/>
  <joint name="RL_foot_joint" type="fixed">
    <origin rpy="0 0 0" xyz="0 0 -0.25116"/>
    <parent link="RL_lower_leg_link"/>
    <child link="RL_foot_link"/>
    <axis xyz="0 0 0"/>
  </joint>
  <!-- <xacro:if value="${is_gazebo}"> -->
  <!-- <gazebo> -->
  <!-- <plugin -->
  <!-- name="gazebo_ros_control" -->
  <!-- filename="libgazebo_ros_control.so"> -->
  <!-- <robotNamespace>/right_arm</robotNamespace> -->
  <!-- </plugin> -->
  <!-- </gazebo> -->
  <!-- </xacro:if> -->
</robot>
