<?xml version="1.0"?>

<!-- XML namespaces -->
<robot xmlns:xacro="http://ros.org/wiki/xacro">

  <!-- ============================  link  ============================ -->
  <!-- Includes elbow flex, FA roll joints in macros below -->
  <xacro:macro name="jelly_leg_v1" params="side parent f_sign s_sign hip_r hip_y leg_y">
    <link
      name="${side}_hip_link">
      <inertial>
        <origin
          xyz="-0.050171 -0.014879 2.5931E-05"
          rpy="${hip_r} 0 ${hip_y}" />
        <mass
          value="0.39719" />
        <inertia
          ixx="0.0004047"
          ixy="0.00028697"
          ixz="2.6664E-07"
          iyy="0.00044289"
          iyz="-3.1906E-07"
          izz="0.00079608" />
      </inertial>
      <visual>
        <origin
          xyz="0 0 0"
          rpy="${hip_r} 0 ${hip_y}" />
        <geometry>
          <mesh
            filename="package://jelly_descriptions/meshes/hip_link.STL" />
        </geometry>
        <material
          name="">
          <color
            rgba="0.89804 0.91765 0.92941 1" />
        </material>
      </visual>
      <collision>
        <origin
          xyz="${hip_r} 0 ${hip_y}"
          rpy="0 0 0" />
        <geometry>
          <mesh
            filename="package://jelly_descriptions/meshes/hip_link.STL" />
        </geometry>
      </collision>
    </link>
    <joint
      name="${side}_hip_joint"
      type="continuous">
      <origin
        xyz="${0.28135*f_sign} ${-0.11*s_sign} 0"
        rpy="0 0 0" />
      <parent
        link="${parent}" />
      <child
        link="${side}_hip_link" />
      <axis
        xyz="${1 * s_sign} 0 0" />
    </joint>

    <link
      name="${side}_upper_leg_link">
      <inertial>
        <origin
          xyz="0.0002142 -0.021966 -0.12486"
          rpy="0 0 ${leg_y}" />
        <mass
          value="0.6645" />
        <inertia
          ixx="0.0067989"
          ixy="2.0009E-06"
          ixz="6.14E-07"
          iyy="0.0067314"
          iyz="1.4199E-06"
          izz="0.00018916" />
      </inertial>
      <visual>
        <origin
          xyz="0 0 0"
          rpy="0 0 ${leg_y}" />
        <geometry>
          <mesh
            filename="package://jelly_descriptions/meshes/upper_leg_link.STL" />
        </geometry>
        <material
          name="">
          <color
            rgba="0.19804 0.11765 0.12941 1" />
        </material>
      </visual>
      <collision>
        <origin
          xyz="0 0 0"
          rpy="0 0 ${leg_y}" />
        <geometry>
          <mesh
            filename="package://jelly_descriptions/meshes/upper_leg_link.STL" />
        </geometry>
      </collision>
    </link>
    <joint
      name="${side}_upper_leg_joint"
      type="continuous">
      <origin
        xyz="0 ${-0.046*s_sign} 0"
        rpy="0 0 0" />
      <parent
        link="${side}_hip_link" />
      <child
        link="${side}_upper_leg_link" />
      <axis
        xyz="0 1 0" />
    </joint>
    <link
      name="${side}_lower_leg_link">
      <inertial>
        <origin
          xyz="-1.4945E-06 -0.011905 -0.12333"
          rpy="0 0 ${leg_y}" />
        <mass
          value="0.17273" />
        <inertia
          ixx="0.0018547"
          ixy="-6.8019E-09"
          ixz="3.1812E-08"
          iyy="0.0017651"
          iyz="0.00025365"
          izz="8.9626E-05" />
      </inertial>
      <visual>
        <origin
          xyz="0 0 0"
          rpy="0 0 ${leg_y}" />
        <geometry>
          <mesh
            filename="package://jelly_descriptions/meshes/lower_leg_link.STL" />
        </geometry>
        <material
          name="">
          <color
            rgba="0.89804 0.91765 0.92941 1" />
        </material>
      </visual>
      <collision>
        <origin
          xyz="0 0 0"
          rpy="0 0 ${leg_y}" />
        <geometry>
          <mesh
            filename="package://jelly_descriptions/meshes/lower_leg_link.STL" />
        </geometry>
      </collision>
    </link>
    <joint
      name="${side}_lower_leg_joint"
      type="continuous">
      <origin
        xyz="0 0 -0.25"
        rpy="0 0 0" />
      <parent
        link="${side}_upper_leg_link" />
      <child
        link="${side}_lower_leg_link" />
      <axis
        xyz="0 1 0" />
    </joint>
    <link
      name="${side}_foot_link" />
    <joint
      name="${side}_foot_joint"
      type="fixed">
      <origin
        xyz="0 0 -0.25116"
        rpy="0 0 0" />
      <parent
        link="${side}_lower_leg_link" />
      <child
        link="${side}_foot_link" />
      <axis
        xyz="0 0 0" />
    </joint>
  </xacro:macro>
</robot>
